Workbook

Sheet 보장분석 비교
A1: 보장분석 비교
A2: 고객명: | N2: 세 님 보장 분석표(기존) | X2: 세 님 보장 분석표 (리모델링)
A3: 생성일: 2026-05-14 11:49:27
K4: 납입완료 | M4: 납입완료 | N4: 납입완료 | P4: 납입완료 | X4: 납입완료 | Z4: 납입완료
R5: 리모델링 전 | S5: 보험사 | V5: 리모델링 후
S6: 상품명
S8: 가입일자
S9: 납입기간(년)
S10: 만기
B11: =IF(DATEDIF(B8,TODAY()+1,"m")<B15,DATEDIF(B8,TODAY()+1,"m"),B9*12) | C11: =IF(DATEDIF(C8,TODAY()+1,"m")<C15,DATEDIF(C8,TODAY()+1,"m"),C9*12) | D11: =IF(DATEDIF(D8,TODAY()+1,"m")<D15,DATEDIF(D8,TODAY()+1,"m"),D9*12) | E11: =IF(DATEDIF(E8,TODAY()+1,"m")<E15,DATEDIF(E8,TODAY()+1,"m"),E9*12) | F11: =IF(DATEDIF(F8,TODAY()+1,"m")<F15,DATEDIF(F8,TODAY()+1,"m"),F9*12) | G11: =IF(DATEDIF(G8,TODAY()+1,"m")<G15,DATEDIF(G8,TODAY()+1,"m"),G9*12) | H11: =IF(DATEDIF(H8,TODAY()+1,"m")<H15,DATEDIF(H8,TODAY()+1,"m"),H9*12) | I11: =IF(DATEDIF(I8,TODAY()+1,"m")<I15,DATEDIF(I8,TODAY()+1,"m"),I9*12) | ... Q11: =IF(DATEDIF(Q8,TODAY()+1,"m")<Q15,DATEDIF(Q8,TODAY()+1,"m"),Q9*12) | S11: 현재까지 납입 횟수 | W11: =IF(DATEDIF(W8,TODAY()+1,"m")<W15,DATEDIF(W8,TODAY()+1,"m"),W9*12) | X11: =IF(DATEDIF(X8,TODAY()+1,"m")<X15,DATEDIF(X8,TODAY()+1,"m"),X9*12) | Y11: =IF(DATEDIF(Y8,TODAY()+1,"m")<Y15,DATEDIF(Y8,TODAY()+1,"m"),Y9*12) | Z11: =IF(DATEDIF(Z8,TODAY()+1,"m")<Z15,DATEDIF(Z8,TODAY()+1,"m"),Z9*12) | AC11: =IF(DATEDIF(AC8,TODAY()+1,"m")<AC15,DATEDIF(AC8,TODAY()+1,"m"),AC9*12) | AD11: =IF(DATEDIF(AD8,TODAY()+1,"m")<AD15,DATEDIF(AD8,TODAY()+1,"m"),AD9*12) | AE11: =IF(DATEDIF(AE8,TODAY()+1,"m")<AE15,DATEDIF(AE8,TODAY()+1,"m"),AE9*12) | AF11: =IF(DATEDIF(AF8,TODAY()+1,"m")<AF15,DATEDIF(AF8,TODAY()+1,"m"),AF9*12)
B12: =B11*B65 | C12: =C11*C65 | D12: =D11*D65 | E12: =E11*E65 | F12: =F11*F65 | G12: =G11*G65 | H12: =H11*H65 | I12: =I11*I65 | ... Q12: =Q11*Q65 | R12: =SUM(B12:Q12) | V12: =SUM(AA12:AF12) | W12: =W11*W65 | X12: =X11*X65 | Y12: =Y11*Y65 | Z12: =Z11*Z65 | AC12: =AC11*AC65 | AD12: =AD11*AD65 | AE12: =AE11*AE65 | AF12: =AF11*AF65
B13: =(B9*12)-B11 | C13: =(C9*12)-C11 | D13: =(D9*12)-D11 | E13: =(E9*12)-E11 | F13: =(F9*12)-F11 | G13: =(G9*12)-G11 | H13: =(H9*12)-H11 | I13: =(I9*12)-I11 | ... Q13: =(Q9*12)-Q11 | S13: 잔여 납입 횟수 | W13: =(W9*12)-W11 | X13: =(X9*12)-X11 | Y13: =(Y9*12)-Y11 | Z13: =(Z9*12)-Z11 | AC13: =(AC9*12)-AC11 | AD13: =(AD9*12)-AD11 | AE13: =(AE9*12)-AE11 | AF13: =(AF9*12)-AF11
B14: =B13*B65 | C14: =C13*C65 | D14: =D13*D65 | E14: =E13*E65 | F14: =F13*F65 | G14: =G13*G65 | H14: =H13*H65 | I14: =I13*I65 | ... Q14: =Q13*Q65 | R14: =SUM(B14:Q14) | V14: =SUM(AA14:AF14) | W14: =W13*W65 | X14: =X13*X65 | Y14: =Y13*Y65 | Z14: =Z13*Z65 | AC14: =AC13*AC65 | AD14: =AD13*AD65 | AE14: =AE13*AE65 | AF14: =AF13*AF65
B15: =B9*12 | C15: =C9*12 | D15: =D9*12 | E15: =E9*12 | F15: =F9*12 | G15: =G9*12 | H15: =H9*12 | I15: =I9*12 | ... Q15: =Q9*12 | S15: 총 납입 횟수 | W15: =W9*12 | X15: =X9*12 | Y15: =Y9*12 | Z15: =Z9*12 | AC15: =AC9*12 | AD15: =AD9*12 | AE15: =AE9*12 | AF15: =AF9*12
B16: =B15*B65 | C16: =C15*C65 | D16: =D15*D65 | E16: =E15*E65 | F16: =F15*F65 | G16: =G15*G65 | H16: =H15*H65 | I16: =I15*I65 | ... Q16: =Q15*Q65 | R16: =SUM(B16:Q16) | V16: =SUM(AA16:AF16) | W16: =W15*W65 | X16: =X15*X65 | Y16: =Y15*Y65 | Z16: =Z15*Z65 | AD16: =AD15*AD65 | AE16: =AE15*AE65 | AF16: =AF15*AF65
R17: =SUM(B17:Q17) | S17: 일반사망 | V17: =SUM(W17:AF17)
R18: =SUM(B18:Q18) | S18: 재해사망 | V18: =SUM(W18:AF18)
R19: =SUM(B19:Q19) | S19: 질병사망 | V19: =SUM(W19:AF19)
R20: =SUM(B20:Q20) | S20: 상해사망 | V20: =SUM(W20:AF20)
R21: =SUM(B21:Q21) | S21: 상해 후유장해 3% | V21: =SUM(W21:AF21)
R22: =SUM(B22:Q22) | S22: 질병 후유장해 3% | V22: =SUM(W22:AF22)
R23: =SUM(B23:Q23) | S23: 일반암(유사암제외) | V23: =SUM(W23:AF23)
R24: =SUM(B24:Q24) | S24: 유사암 / 소액암 | V24: =SUM(W24:AF24)
R25: =SUM(B25:Q25) | S25: 암수술 | V25: =SUM(W25:AF25)
R26: =SUM(B26:Q26) | S26: 항암방사선·항암약물 | V26: =SUM(W26:AF26)
R27: =SUM(B27:Q27) | S27: 표적항암약물 | V27: =SUM(W27:AF27)
R28: =SUM(B28:Q28) | S28: 뇌혈관 진단비 | V28: =SUM(W28:AF28)
... R57: =SUM(B57:Q57) | S57: 자동차사고부상 | V57: =SUM(W57:AF57)
R58: =SUM(B58:Q58) | S58: 벌 금 | T58: 대인 | V58: =SUM(W58:AF58)
R59: =SUM(B59:Q59) | T59: 대물 | V59: =SUM(W59:AF59)
R60: =SUM(B60:Q60) | S60: 합 의 | T60: 사망/중상해 | V60: =SUM(W60:AF60)
R61: =SUM(B61:Q61) | T61: 6주미만 | V61: =SUM(W61:AF61)
R62: =SUM(B62:Q62) | S62: 변호사선임비용 | V62: =SUM(W62:AF62)
R63: =SUM(B63:Q63) | S63: 일상배상책임보험 | V63: =SUM(W63:AF63)
S64: 실비
R65: =SUM(B65:Q65) | V65: =SUM(W65:AF65)
R66: 대장용종제거 | S66: 전/후 차이금액 | V66: 대장용종제거
R67: =R43+R45 | S67: =V65-R65 | V67: =V43+V45
R68: 체외충격파쇄석술 | V68: 체외충격파쇄석술
R69: =R45 | V69: =V45
...

Sheet 전후비교
D1: 세 | E1: 님 보장 분석표 | I1: 전후비교
D2: 전/후 | E2: 기존 보험 | G2: 리모델링 | I2: 권장 금액 | J2: 보장 진단
A4: 구 성 | B4: 보험료 | D4: =G4-E4 | E4: =SUM('보장분석 비교'!R65) | G4: ='보장분석 비교'!V65
A6: 실 비 | B6: 실손의료비 | E6: ='보장분석 비교'!Q64 | G6: ='보장분석 비교'!$C11 | J6: =IF(I6=0,"",IF(I6>G6,"부족","!!충분!!"))
A7: 사망 | B7: 일반 사망 | D7: =G7-E7 | E7: ='보장분석 비교'!$R17 | G7: ='보장분석 비교'!$V17 | J7: =IF(I7=0,"",IF(I7>G7,"부족","!!충분!!"))
B8: 재해 사망 | D8: =G8-E8 | E8: ='보장분석 비교'!$R18 | G8: ='보장분석 비교'!$V18
B9: 상해 사망 | D9: =G9-E9 | E9: ='보장분석 비교'!$R19 | G9: ='보장분석 비교'!$V19 | I9: 20000 | J9: =IF(I9=0,"",IF(I9>G9,"부족","!!충분!!"))
B10: 질병 사망 | D10: =G10-E10 | E10: ='보장분석 비교'!$R20 | G10: ='보장분석 비교'!$V20 | I10: 10000 | J10: =IF(I10=0,"",IF(I10>G10,"부족","!!충분!!"))
A11: 후유장해 | B11: 0.03 | C11: 상해(재해)후유장해 | D11: =G11-E11 | E11: ='보장분석 비교'!$R21 | G11: ='보장분석 비교'!$V21 | I11: 10000 | J11: =IF(I11=0,"",IF(I11>G11,"부족","!!충분!!"))
C12: 질병후유장해 | D12: =G12-E12 | E12: ='보장분석 비교'!$R22 | G12: ='보장분석 비교'!$V22 | I12: 5000 | J12: =IF(I12=0,"",IF(I12>G12,"부족","!!충분!!"))
A13: 암 | B13: 일반암 진단비 | D13: =G13-E13 | E13: ='보장분석 비교'!$R23 | G13: ='보장분석 비교'!$V23 | I13: 10000 | J13: =IF(I13=0,"",IF(I13>G13,"부족","!!충분!!"))
B14: 소액/유사암 진단비 | D14: =G14-E14 | E14: ='보장분석 비교'!$R24 | G14: ='보장분석 비교'!$V24 | I14: 3000 | J14: =IF(I14=0,"",IF(I14>G14,"부족","!!충분!!"))
B15: 암직접치료 입원일당 | D15: =G15-E15 | E15: ='보장분석 비교'!#REF! | G15: ='보장분석 비교'!#REF! | J15: =IF(I15=0,"",IF(I15>G15,"부족","!!충분!!"))
B16: 항암약물방사선 치료비 | D16: =G16-E16 | E16: ='보장분석 비교'!$R26 | G16: ='보장분석 비교'!$V26 | J16: =IF(I16=0,"",IF(I16>G16,"부족","!!충분!!"))
B17: 표적항암약물허가 치료비 | D17: =G17-E17 | E17: ='보장분석 비교'!$R27 | G17: ='보장분석 비교'!$V27 | I17: 5000 | J17: =IF(I17=0,"",IF(I17>G17,"부족","!!충분!!"))
A18: 뇌질환 | C18: 뇌혈관질환 진단비 | D18: =G18-E18 | E18: ='보장분석 비교'!$R28 | G18: ='보장분석 비교'!$V28 | I18: 3000 | J18: =IF(I18=0,"",IF(I18>G18,"부족","!!충분!!"))
C19: 뇌혈관질환 수술비 | D19: =G19-E19 | E19: ='보장분석 비교'!$R29 | G19: ='보장분석 비교'!$V29 | J19: =IF(I19=0,"",IF(I19>G19,"부족","!!충분!!"))
C20: 뇌졸중 진단비 | D20: =G20-E20 | E20: ='보장분석 비교'!$R30 | G20: ='보장분석 비교'!$V30 | I20: 1000 | J20: =IF(I20=0,"",IF(I20>G20,"부족","!!충분!!"))
C21: 뇌출혈 진단비 | D21: =G21-E21 | E21: ='보장분석 비교'!$R31 | G21: ='보장분석 비교'!$V31 | I21: 1000 | J21: =IF(I21=0,"",IF(I21>G21,"부족","!!충분!!"))
A22: 심질환 | C22: 허혈성심장질환 진단비 | D22: =G22-E22 | E22: ='보장분석 비교'!$R32 | G22: ='보장분석 비교'!$V32 | I22: 3000 | J22: =IF(I22=0,"",IF(I22>G22,"부족","!!충분!!"))
C23: 허혈성심장질환 수술비 | D23: =G23-E23 | E23: ='보장분석 비교'!$R33 | G23: ='보장분석 비교'!$V33 | J23: =IF(I23=0,"",IF(I23>G23,"부족","!!충분!!"))
C24: 심장혈관 진단비 | D24: =G24-E24 | E24: ='보장분석 비교'!$R34 | G24: ='보장분석 비교'!$V34 | I24: 1000 | J24: =IF(I24=0,"",IF(I24>G24,"부족","!!충분!!"))
C25: 부정맥 진단비 | D25: =G25-E25 | E25: ='보장분석 비교'!$R35 | G25: ='보장분석 비교'!$V35 | I25: 1000 | J25: =IF(I25=0,"",IF(I25>G25,"부족","!!충분!!"))
C26: 급성심근경색 진단비 | D26: =G26-E26 | E26: ='보장분석 비교'!$R36 | G26: ='보장분석 비교'!$V36 | I26: 7000 | J26: =IF(I26=0,"",IF(I26>G26,"부족","!!충분!!"))
A27: 수술비 | B27: 상 해 | C27: 상해 수술비 | D27: =G27-E27 | E27: ='보장분석 비교'!$R37 | G27: ='보장분석 비교'!$V37 | I27: 100 | J27: =IF(I27=0,"",IF(I27>G27,"부족","!!충분!!"))
C28: 1종 수술비 | D28: =G28-E28 | E28: ='보장분석 비교'!$R38 | G28: ='보장분석 비교'!$V38 | I28: 50 | J28: =IF(I28=0,"",IF(I28>G28,"부족","!!충분!!"))
C29: 2종 수술비 | D29: =G29-E29 | E29: ='보장분석 비교'!$R39 | G29: ='보장분석 비교'!$V39 | I29: 100 | J29: =IF(I29=0,"",IF(I29>G29,"부족","!!충분!!"))
C30: 3종 수술비 | D30: =G30-E30 | E30: ='보장분석 비교'!$R40 | G30: ='보장분석 비교'!$V40 | I30: 200 | J30: =IF(I30=0,"",IF(I30>G30,"부족","!!충분!!"))
C31: 4종 수술비 | D31: =G31-E31 | E31: ='보장분석 비교'!$R41 | G31: ='보장분석 비교'!$V41 | I31: 500 | J31: =IF(I31=0,"",IF(I31>G31,"부족","!!충분!!"))
C32: 5종 수술비 | D32: =G32-E32 | E32: ='보장분석 비교'!$R42 | G32: ='보장분석 비교'!$V42 | I32: 1000 | J32: =IF(I32=0,"",IF(I32>G32,"부족","!!충분!!"))
B33: 질 병 | C33: 질병 수술비 | D33: =G33-E33 | E33: ='보장분석 비교'!$R43 | G33: ='보장분석 비교'!$V43 | I33: 50 | J33: =IF(I33=0,"",IF(I33>G33,"부족","!!충분!!"))
C34: 1종 수술비 | D34: =G34-E34 | E34: ='보장분석 비교'!$R44 | G34: ='보장분석 비교'!$V44 | I34: 10 | J34: =IF(I34=0,"",IF(I34>G34,"부족","!!충분!!"))
C35: 2종 수술비 | D35: =G35-E35 | E35: ='보장분석 비교'!$R45 | G35: ='보장분석 비교'!$V45 | I35: 20 | J35: =IF(I35=0,"",IF(I35>G35,"부족","!!충분!!"))
C36: 3종 수술비 | D36: =G36-E36 | E36: ='보장분석 비교'!$R46 | G36: ='보장분석 비교'!$V46 | I36: 100 | J36: =IF(I36=0,"",IF(I36>G36,"부족","!!충분!!"))
C37: 4종 수술비 | D37: =G37-E37 | E37: ='보장분석 비교'!$R47 | G37: ='보장분석 비교'!$V47 | I37: 500 | J37: =IF(I37=0,"",IF(I37>G37,"부족","!!충분!!"))
C38: 5종 수술비 | D38: =G38-E38 | E38: ='보장분석 비교'!$R48 | G38: ='보장분석 비교'!$V48 | I38: 1000 | J38: =IF(I38=0,"",IF(I38>G38,"부족","!!충분!!"))
A39: 입원 | B39: 상해 입원일당 | D39: =G39-E39 | E39: ='보장분석 비교'!$R49 | G39: ='보장분석 비교'!$V49 | I39: 7 | J39: =IF(I39=0,"",IF(I39>G39,"부족","!!충분!!"))
B40: 질병 입원일당 | D40: =G40-E40 | E40: ='보장분석 비교'!$R50 | G40: ='보장분석 비교'!$V50 | I40: 7 | J40: =IF(I40=0,"",IF(I40>G40,"부족","!!충분!!"))
A41: 추가 보장 | B41: 골절 진단비 | D41: =G41-E41 | E41: ='보장분석 비교'!$R51 | G41: ='보장분석 비교'!$V51 | I41: 50 | J41: =IF(I41=0,"",IF(I41>G41,"부족","!!충분!!"))
B42: 화상 진단비 | D42: =G42-E42 | E42: ='보장분석 비교'!$R52 | G42: ='보장분석 비교'!$V52 | I42: 20 | J42: =IF(I42=0,"",IF(I42>G42,"부족","!!충분!!"))
...

Sheet 해지할회사정리
B2: 해지해야될 회사별 목록 정리
B4: 원금융서비스 김유란 부지점장입니다
B5: 해지하실것들 알려드리겠습니다. 해지후 해지확인서 팩스발송 부탁드리겠습니다 ^^
B6: Fax. 0504-497-2317
B8: 해지할 회사 목록
B10: 회사이름 | C10: 상품명이름 | D10: 납입보험료 | E10: 해지이유 | F10: 고객센터 | G10: 비고
B28: 배서할 회사 목록
B30: 회사이름 | C30: 상품명이름 | D30: 납입보험료 | E30: 배서이유 | F30: 고객센터 | G30: 비고

Sheet 회사고객센터
A1: 손해보험사 고객센터 | D1: 생명보험사 고객센터
A2: 한화손해 | B2: 1566-8000 | D2: 동양생명 | E2: 1577-1004
A3: AIG손해 | B3: 1544-2792 | D3: 흥국생명 | E3: 1588-2288
A4: 롯데손해 | B4: 1588-3344 | D4: 신한라이프 | E4: 1588-5580
A5: DB손해 | B5: 1588-0100 | D5: KB생명 | E5: 1588-3374
A6: 현대해상 | B6: 1588-5656 | D6: KDB생명 | E6: 1588-4040
A7: 농협화재 | B7: 1644-9000 | D7: ABL생명 | E7: 1588-6500
A8: 삼성화재 | B8: 1588-5114 | D8: 푸르덴셜생명 | E8: 1588-3374
A9: MG손해 | B9: 1588-5959 | D9: DGB생명 | E9: 1588-4770
A10: KB손해 | B10: 1544-0114 | D10: 한화생명 | E10: 1588-6363
A11: 흥국화재 | B11: 1688-1688 | D11: 삼성생명 | E11: 1588-3114
A12: 메리츠 | B12: 1566-7711 | D12: 교보생명 | E12: 1588-1001
D13: 미래에셋생명 | E13: 1588-0220
D14: 농협생명 | E14: 1544-4000
D15: 라이나생명 | E15: 1588-0058
D16: 메트라이프생명 | E16: 1588-9600
D17: DB생명 | E17: 1588-3131

Sheet 심뇌혈관보장범위

Sheet 암분류표

Sheet 후유장해지급률

Sheet 고객정보
A1: customer_name | B1: age | C1: gender | D1: total_contracts | E1: monthly_premium | F1: created_at
E2: 4556674 | F2: 2026-05-14 10:32:45

Sheet 계약리스트_추출
A1: no | B1: insurer | C1: product | D1: contract_date | E1: pay_cycle | F1: pay_period | G1: maturity | H1: premium | I1: premium_number
A2: 1 | B2: (무) | C2: 메리츠 운전자 상해 종합보험2411 | D2: 2024-12-13 | E2: 월납 | F2: 20년 | G2: 74세 | H2: 12,440원 | I2: 12440
A3: 2 | B3: 롯데손보 | C3: 무배당 let:drive 운전자보험(2411) | D3: 2024-12-12 | E3: 월납 | F3: 20년 | G3: 74세 | H3: 17,000원 | I3: 17000
A4: 3 | B4: 흥국화재 | C4: 무배당 행복을 多주는 가족사랑보험(1108) | D4: 2011-09-15 | E4: 월납 | F4: 20년 | G4: 100세 | H4: 71,473원 | I4: 71473
A5: 7 | B5: 하나손보 | C5: 무배당 하나 가득담은 운전자보험(2309) | D5: 2023-11-23 | E5: 월납 | F5: 20년 | G5: 73세 | H5: 33,618원 | I5: 33618

Sheet 담보상세_추출
A1: no | B1: pay_type | C1: coverage_name | D1: category | E1: amount | F1: page_no | G1: amount_number | H1: insurer | I1: contract_date | J1: product_name | K1: premium | L1: premium_number | M1: mapped_category
A2: 1 | B2: 정액 | C2: 운전자용 | D2: 교통상해사망[기본계약] 교통상해사망 | E2: 1,000만 | F2: 2 | G2: 10000000 | H2: 서상웅 님의 상품별 가입담보상세 2026-05-14 10:32:45 (55세 ,남자) ※ 기준담보/권장금액 : 기본형(37개)/표준형 메리츠화재 | I2: 2024-12-13 | J2: (무) 메리츠 운전자 상해 종합보험2411 | K2: 12,440원 | L2: 12440 | M2: 상해사망
A3: 2 | B3: 정액 | C3: 외모특정상해수술비[기본계약] | D3: 특정상해수술 | E3: 10만 | F3: 2 | G3: 100000 | H3: 서상웅 님의 상품별 가입담보상세 2026-05-14 10:32:45 (55세 ,남자) ※ 기준담보/권장금액 : 기본형(37개)/표준형 메리츠화재 | I3: 2024-12-13 | J3: (무) 메리츠 운전자 상해 종합보험2411 | K3: 12,440원 | L3: 12440 | M3: 상해수술비
A4: 3 | B4: 실손 | C4: 화재벌금담보 | D4: 화재벌금담보 | E4: 2,000만 | F4: 2 | G4: 20000000 | H4: 서상웅 님의 상품별 가입담보상세 2026-05-14 10:32:45 (55세 ,남자) ※ 기준담보/권장금액 : 기본형(37개)/표준형 메리츠화재 | I4: 2024-12-13 | J4: (무) 메리츠 운전자 상해 종합보험2411 | K4: 12,440원 | L4: 12440 | M4: 운전자 담보
A5: 4 | B5: 실손 | C5: 가전제품고장수리비용 | D5: 가전제품고장수리비용 | E5: 100만 | F5: 2 | G5: 1000000 | H5: 서상웅 님의 상품별 가입담보상세 2026-05-14 10:32:45 (55세 ,남자) ※ 기준담보/권장금액 : 기본형(37개)/표준형 메리츠화재 | I5: 2024-12-13 | J5: (무) 메리츠 운전자 상해 종합보험2411 | K5: 12,440원 | L5: 12440 | M5: 미분류
A6: 1 | B6: 정액 | C6: 골절진단비(치아파절제외) | D6: 골절진단 | E6: 10만 | F6: 3 | G6: 100000 | H6: 서상웅 님의 상품별 가입담보상세 2026-05-14 10:32:45 (55세 ,남자) ※ 기준담보/권장금액 : 기본형(37개)/표준형 롯데손보 | I6: 2024-12-12 | J6: 무배당 let:drive 운전자보험(2411) | K6: 17,000원 | L6: 17000 | M6: 골절/화상
A7: 2 | B7: 정액 | C7: 골절진단비(치아파절포함) | D7: 골절진단 | E7: 10만 | F7: 3 | G7: 100000 | H7: 서상웅 님의 상품별 가입담보상세 2026-05-14 10:32:45 (55세 ,남자) ※ 기준담보/권장금액 : 기본형(37개)/표준형 롯데손보 | I7: 2024-12-12 | J7: 무배당 let:drive 운전자보험(2411) | K7: 17,000원 | L7: 17000 | M7: 골절/화상
A8: 3 | B8: 정액 | C8: 5대골절진단비 | D8: 중대골절진단 | E8: 50만 | F8: 3 | G8: 500000 | H8: 서상웅 님의 상품별 가입담보상세 2026-05-14 10:32:45 (55세 ,남자) ※ 기준담보/권장금액 : 기본형(37개)/표준형 롯데손보 | I8: 2024-12-12 | J8: 무배당 let:drive 운전자보험(2411) | K8: 17,000원 | L8: 17000 | M8: 골절/화상
A9: 4 | B9: 정액 | C9: 상해수술비 | D9: 상해수술 | E9: 50만 | F9: 3 | G9: 500000 | H9: 서상웅 님의 상품별 가입담보상세 2026-05-14 10:32:45 (55세 ,남자) ※ 기준담보/권장금액 : 기본형(37개)/표준형 롯데손보 | I9: 2024-12-12 | J9: 무배당 let:drive 운전자보험(2411) | K9: 17,000원 | L9: 17000 | M9: 상해수술비
A10: 5 | B10: 정액 | C10: 골절철심제거수술비(급여,연간1회한) | D10: 기타수술 | E10: 50만 | F10: 3 | G10: 500000 | H10: 서상웅 님의 상품별 가입담보상세 2026-05-14 10:32:45 (55세 ,남자) ※ 기준담보/권장금액 : 기본형(37개)/표준형 롯데손보 | I10: 2024-12-12 | J10: 무배당 let:drive 운전자보험(2411) | K10: 17,000원 | L10: 17000 | M10: 골절/화상
A11: 6 | B11: 정액 | C11: 상해입원비(1일-180일) | D11: 상해입원일당 | E11: 2만 | F11: 3 | G11: 20000 | H11: 서상웅 님의 상품별 가입담보상세 2026-05-14 10:32:45 (55세 ,남자) ※ 기준담보/권장금액 : 기본형(37개)/표준형 롯데손보 | I11: 2024-12-12 | J11: 무배당 let:drive 운전자보험(2411) | K11: 17,000원 | L11: 17000 | M11: 상해입원일당
A12: 7 | B12: 정액 | C12: 교통상해입원비(1일-180일) | D12: 교통상해입원일당 | E12: 1만 | F12: 3 | G12: 10000 | H12: 서상웅 님의 상품별 가입담보상세 2026-05-14 10:32:45 (55세 ,남자) ※ 기준담보/권장금액 : 기본형(37개)/표준형 롯데손보 | I12: 2024-12-12 | J12: 무배당 let:drive 운전자보험(2411) | K12: 17,000원 | L12: 17000 | M12: 상해입원일당
A13: 8 | B13: 정액 | C13: 종합병원상해입원비(1일-180일) | D13: 종합병원이하 상해입원일당 | E13: 3만 | F13: 3 | G13: 30000 | H13: 서상웅 님의 상품별 가입담보상세 2026-05-14 10:32:45 (55세 ,남자) ※ 기준담보/권장금액 : 기본형(37개)/표준형 롯데손보 | I13: 2024-12-12 | J13: 무배당 let:drive 운전자보험(2411) | K13: 17,000원 | L13: 17000 | M13: 상해입원일당
... A152: 12 | B152: 정액 | C152: 항암 중입자방사선치료특약(3.10.5 간편고지, | D152: 갱신형) 최초계약 고액항암치료비 | E152: 5,000만 | F152: 12 | G152: 50000000 | H152: 서상웅 님의 상품별 가입담보상세 2026-05-14 10:32:45 (55세 ,남자) ※ 기준담보/권장금액 : 기본형(37개)/표준형 미래에셋생명 | I152: 2026-01-26 | J152: M-케어 건강보험(3.10.5 간편고지, 갱신형) 무배당 | K152: 101,522원 | L152: 101522 | M152: 중입자치료비
A153: 1 | B153: 정액 | C153: 특정질병사망 | D153: 특정질병사망 | E153: 6,100만 | F153: 13 | G153: 61000000 | H153: 서상웅 님의 상품별 가입담보상세 2026-05-14 10:32:45 (55세 ,남자) ※ 기준담보/권장금액 : 기본형(37개)/표준형 NH농협생명 | I153: 2025-08-29 | K153: 96,500원 | L153: 96500 | M153: 미분류
A154: 2 | B154: 정액 | C154: 특정상해사망 | D154: 특정상해사망 | E154: 6,100만 | F154: 13 | G154: 61000000 | H154: 서상웅 님의 상품별 가입담보상세 2026-05-14 10:32:45 (55세 ,남자) ※ 기준담보/권장금액 : 기본형(37개)/표준형 NH농협생명 | I154: 2025-08-29 | K154: 96,500원 | L154: 96500 | M154: 상해사망
A155: 3 | B155: 정액 | C155: 특정질병후유장해 | D155: 특정질병후유장해 | E155: 6,000만 | F155: 13 | G155: 60000000 | H155: 서상웅 님의 상품별 가입담보상세 2026-05-14 10:32:45 (55세 ,남자) ※ 기준담보/권장금액 : 기본형(37개)/표준형 NH농협생명 | I155: 2025-08-29 | K155: 96,500원 | L155: 96500 | M155: 후유장해
A156: 4 | B156: 정액 | C156: 특정상해후유장해 | D156: 특정상해후유장해 | E156: 6,000만 | F156: 13 | G156: 60000000 | H156: 서상웅 님의 상품별 가입담보상세 2026-05-14 10:32:45 (55세 ,남자) ※ 기준담보/권장금액 : 기본형(37개)/표준형 NH농협생명 | I156: 2025-08-29 | K156: 96,500원 | L156: 96500 | M156: 후유장해
A157: 5 | B157: 정액 | C157: 특정질병진단 | D157: 특정질병진단 | E157: 30만 | F157: 13 | G157: 300000 | H157: 서상웅 님의 상품별 가입담보상세 2026-05-14 10:32:45 (55세 ,남자) ※ 기준담보/권장금액 : 기본형(37개)/표준형 NH농협생명 | I157: 2025-08-29 | K157: 96,500원 | L157: 96500 | M157: 미분류
A158: 6 | B158: 정액 | C158: 특정상해진단 | D158: 특정상해진단 | E158: 30만 | F158: 13 | G158: 300000 | H158: 서상웅 님의 상품별 가입담보상세 2026-05-14 10:32:45 (55세 ,남자) ※ 기준담보/권장금액 : 기본형(37개)/표준형 NH농협생명 | I158: 2025-08-29 | K158: 96,500원 | L158: 96500 | M158: 미분류
A159: 7 | B159: 정액 | C159: 기타수술 | D159: 기타수술 | E159: 30만 | F159: 13 | G159: 300000 | H159: 서상웅 님의 상품별 가입담보상세 2026-05-14 10:32:45 (55세 ,남자) ※ 기준담보/권장금액 : 기본형(37개)/표준형 NH농협생명 | I159: 2025-08-29 | K159: 96,500원 | L159: 96500 | M159: 미분류
A160: 8 | B160: 정액 | C160: 특정상해입원일당 | D160: 특정상해입원일당 | E160: 2만 | F160: 13 | G160: 20000 | H160: 서상웅 님의 상품별 가입담보상세 2026-05-14 10:32:45 (55세 ,남자) ※ 기준담보/권장금액 : 기본형(37개)/표준형 NH농협생명 | I160: 2025-08-29 | K160: 96,500원 | L160: 96500 | M160: 상해입원일당
A161: 9 | B161: 정액 | C161: 기타입원일당 | D161: 기타입원일당 | E161: 2만 | F161: 13 | G161: 20000 | H161: 서상웅 님의 상품별 가입담보상세 2026-05-14 10:32:45 (55세 ,남자) ※ 기준담보/권장금액 : 기본형(37개)/표준형 NH농협생명 | I161: 2025-08-29 | K161: 96,500원 | L161: 96500 | M161: 미분류
A162: 10 | B162: 실손 | C162: 농업작업안전 | D162: 재해 및 질병 농업작업안전 재해 및 질병입원의료비 | E162: 5,000만 | F162: 13 | G162: 50000000 | H162: 서상웅 님의 상품별 가입담보상세 2026-05-14 10:32:45 (55세 ,남자) ※ 기준담보/권장금액 : 기본형(37개)/표준형 NH농협생명 | I162: 2025-08-29 | K162: 96,500원 | L162: 96500 | M162: 실손의료비
A163: 11 | B163: 실손 | C163: 농업작업안전 | D163: 재해 및 질병 농업작업안전 재해 및 질병처방조제료 | E163: 10만 | F163: 13 | G163: 100000 | H163: 서상웅 님의 상품별 가입담보상세 2026-05-14 10:32:45 (55세 ,남자) ※ 기준담보/권장금액 : 기본형(37개)/표준형 NH농협생명 | I163: 2025-08-29 | K163: 96,500원 | L163: 96500 | M163: 실손의료비
A164: 12 | B164: 실손 | C164: 농업작업안전 | D164: 재해 및 질병 농업작업안전 재해 및 질병외래의료비 | E164: 20만 | F164: 13 | G164: 200000 | H164: 서상웅 님의 상품별 가입담보상세 2026-05-14 10:32:45 (55세 ,남자) ※ 기준담보/권장금액 : 기본형(37개)/표준형 NH농협생명 | I164: 2025-08-29 | K164: 96,500원 | L164: 96500 | M164: 실손의료비

Sheet 자동분류_요약
A1: 분류 | B1: 가입금액합계 | C1: 담보수 | D1: 대표담보
A2: 간병인 입원일당 | B2: 300000 | C2: 2 | D2: [간편]상해 입원 간병인 사용일당(181일이상,요양/정신/한방제외) / [간편]질병 입원 간병인 사용일당(181일이상,요양/정신/한방제외,1년감액)
A3: 골절/화상 | B3: 5600000 | C3: 14 | D3: 골절진단비(치아파절제외) / 골절진단비(치아파절포함) / 5대골절진단비 / 골절철심제거수술비(급여,연간1회한) / 골절진단비(치아파절제외)(통합간편가입형)(갱신형_20년
A4: 뇌혈관 수술비 | B4: 10000000 | C4: 1 | D4: 뇌혈관질환수술비Ⅱ(통합간편가입형)(갱신형_20년)
A5: 뇌혈관 진단비 | B5: 10000000 | C5: 1 | D5: 뇌혈관질환진단비Ⅱ(통합간편가입형)(갱신형_20년)
A6: 미분류 | B6: 318500000 | C6: 55 | D6: 가전제품고장수리비용 / 깁스치료비 / 조혈모세포이식수술비 / 갑상선 바늘생검 조직병리 진단비(급여_연간1회한)(통합 / 대상포진눈병진단비(통합간편가입형)(갱신형_20년)
A7: 상해사망 | B7: 224000000 | C7: 10 | D7: 운전자용 / 일반상해사망 / 일반상해사망(통합간편가입형)(갱신형_20년) / [유병자형]상해 / [간편]상해
A8: 상해수술비 | B8: 24130000 | C8: 6 | D8: 외모특정상해수술비[기본계약] / 상해수술비 / 상해수술비 / 상해수술비(1~8종,연간1회한)(8종) / 5대골절수술비
A9: 상해입원일당 | B9: 1120000 | C9: 14 | D9: 상해입원비(1일-180일) / 교통상해입원비(1일-180일) / 종합병원상해입원비(1일-180일) / 일반상해입원비(1일-180일) / [간편]상해
A10: 세기조절방사선치료비 | B10: 10000000 | C10: 1 | D10: 항암 세기조절방사선치료특약(3.10.5 간편고지,
A11: 실손의료비 | B11: 150900000 | C11: 9 | D11: 상해(일반상해,전체상해를 의미) 상해(일반상해,전체상해를 / 상해(일반상해,전체상해를 의미) 상해(일반상해,전체상해를 / 상해(일반상해,전체상해를 의미) 상해(일반상해,전체상해를 / 질병(전체질병을 / 질병(전체질병을
A12: 양성자치료비 | B12: 20000000 | C12: 1 | D12: 항암 양성자방사선치료특약(3.10.5 간편고지,
A13: 운전자 담보 | B13: 372300000 | C13: 13 | D13: 화재벌금담보 / 자동차사고부상Ⅱ(1~3급) / 자동차사고부상Ⅱ(1~7급) / 교통사고 / 자동차사고
... A22: 후유장해 | B22: 340000000 | C22: 6 | D22: 일반상해후유장해 / 일반상해후유장해 / 일반상해후유장해(3~100%) / 교통상해50%이상후유장해생활지원금(10년,월지급형) / 특정질병후유장해
