Workbook

Sheet 보장분석 비교
N2: 세 님 보장 분석표(기존) | X2: 세 님 보장 분석표 (리모델링)
K4: 납입완료 | M4: 납입완료 | N4: 납입완료 | P4: 납입완료 | X4: 납입완료 | Z4: 납입완료
R5: 리모델링 전 | S5: 보험사 | V5: 리모델링 후
S6: 상품명
S8: 가입일자
S9: 납입기간(년)
S10: 만기
R11: =SUM(B11:Q11) -> 0 | S11: 일반사망 | V11: =SUM(W11:AF11) -> 0
R12: =SUM(B12:Q12) -> 0 | S12: 재해사망 | V12: =SUM(W12:AF12) -> 0
R13: =SUM(B13:Q13) -> 0 | S13: 질병사망 | V13: =SUM(W13:AF13) -> 0
R14: =SUM(B14:Q14) -> 0 | S14: 상해사망 | V14: =SUM(W14:AF14) -> 0
R15: =SUM(B15:Q15) -> 0 | S15: 상해 후유장해 3% | V15: =SUM(W15:AF15) -> 0
R16: =SUM(B16:Q16) -> 0 | S16: 질병 후유장해 3% | V16: =SUM(W16:AF16) -> 0
R17: =SUM(B17:Q17) -> 0 | S17: 일반암(유사암제외) | V17: =SUM(W17:AF17) -> 0
R18: =SUM(B18:Q18) -> 0 | S18: 유사암 / 소액암 | V18: =SUM(W18:AF18) -> 0
R19: =SUM(B19:Q19) -> 0 | S19: 암수술 | V19: =SUM(W19:AF19) -> 0
R20: =SUM(B20:Q20) -> 0 | S20: 항암방사선·항암약물 | V20: =SUM(W20:AF20) -> 0
R21: =SUM(B21:Q21) -> 0 | S21: 표적항암약물 | V21: =SUM(W21:AF21) -> 0
R22: =SUM(B22:Q22) -> 0 | S22: 뇌혈관 진단비 | V22: =SUM(W22:AF22) -> 0
... R51: =SUM(B51:Q51) -> 0 | S51: 자동차사고부상 | V51: =SUM(W51:AF51) -> 0
R52: =SUM(B52:Q52) -> 0 | S52: 벌 금 | T52: 대인 | V52: =SUM(W52:AF52) -> 0
R53: =SUM(B53:Q53) -> 0 | T53: 대물 | V53: =SUM(W53:AF53) -> 0
R54: =SUM(B54:Q54) -> 0 | S54: 합 의 | T54: 사망/중상해 | V54: =SUM(W54:AF54) -> 0
R55: =SUM(B55:Q55) -> 0 | T55: 6주미만 | V55: =SUM(W55:AF55) -> 0
R56: =SUM(B56:Q56) -> 0 | S56: 변호사선임비용 | V56: =SUM(W56:AF56) -> 0
R57: =SUM(B57:Q57) -> 0 | S57: 일상배상책임보험 | V57: =SUM(W57:AF57) -> 0
S58: 실비
R59: =SUM(B59:Q59) -> 0 | V59: =SUM(W59:AF59) -> 0
R60: 대장용종제거 | S60: 전/후 차이금액 | V60: 대장용종제거
R61: =R37+R39 -> 0 | S61: =V59-R59 -> 0 | V61: =V37+V39 -> 0
R62: 체외충격파쇄석술 | V62: 체외충격파쇄석술
R63: =R39 -> 0 | V63: =V39 -> 0
R64: 골절진단/수술 | V64: 골절진단/수술
R65: =R45+R31 -> 0 | V65: =V45+V31 -> 0
R66: 후유장해 5% | V66: 후유장해 5%
R67: =R15*0.05 -> 0 | V67: =V15*0.05 -> 0
H68: 원금융서비스 / FAX | V68: 원금융서비스 / FAX

Sheet 전후비교
D1: 세 | E1: 님 보장 분석표 | I1: 전후비교
D2: 전/후 | E2: 기존 보험 | G2: 리모델링 | I2: 권장 금액 | J2: 보장 진단
A4: 구 성 | B4: 보험료 | D4: =G4-E4 -> 0 | E4: =SUM('보장분석 비교'!R59) -> 0 | G4: ='보장분석 비교'!V59 -> 0
A6: 실 비 | B6: 실손의료비 | E6: ='보장분석 비교'!Q58 -> 0 | G6: ='보장분석 비교'!#REF! -> #REF! | J6: =IF(I6=0,"",IF(I6>G6,"부족","!!충분!!"))
A7: 사망 | B7: 일반 사망 | D7: =G7-E7 -> 0 | E7: ='보장분석 비교'!$R11 -> 0 | G7: ='보장분석 비교'!$V11 -> 0 | J7: =IF(I7=0,"",IF(I7>G7,"부족","!!충분!!"))
B8: 재해 사망 | D8: =G8-E8 -> 0 | E8: ='보장분석 비교'!$R12 -> 0 | G8: ='보장분석 비교'!$V12 -> 0
B9: 상해 사망 | D9: =G9-E9 -> 0 | E9: ='보장분석 비교'!$R13 -> 0 | G9: ='보장분석 비교'!$V13 -> 0 | I9: 20000 | J9: =IF(I9=0,"",IF(I9>G9,"부족","!!충분!!")) -> 부족
B10: 질병 사망 | D10: =G10-E10 -> 0 | E10: ='보장분석 비교'!$R14 -> 0 | G10: ='보장분석 비교'!$V14 -> 0 | I10: 10000 | J10: =IF(I10=0,"",IF(I10>G10,"부족","!!충분!!")) -> 부족
A11: 후유장해 | B11: 0.03 | C11: 상해(재해)후유장해 | D11: =G11-E11 -> 0 | E11: ='보장분석 비교'!$R15 -> 0 | G11: ='보장분석 비교'!$V15 -> 0 | I11: 10000 | J11: =IF(I11=0,"",IF(I11>G11,"부족","!!충분!!")) -> 부족
C12: 질병후유장해 | D12: =G12-E12 -> 0 | E12: ='보장분석 비교'!$R16 -> 0 | G12: ='보장분석 비교'!$V16 -> 0 | I12: 5000 | J12: =IF(I12=0,"",IF(I12>G12,"부족","!!충분!!")) -> 부족
A13: 암 | B13: 일반암 진단비 | D13: =G13-E13 -> 0 | E13: ='보장분석 비교'!$R17 -> 0 | G13: ='보장분석 비교'!$V17 -> 0 | I13: 10000 | J13: =IF(I13=0,"",IF(I13>G13,"부족","!!충분!!")) -> 부족
B14: 소액/유사암 진단비 | D14: =G14-E14 -> 0 | E14: ='보장분석 비교'!$R18 -> 0 | G14: ='보장분석 비교'!$V18 -> 0 | I14: 3000 | J14: =IF(I14=0,"",IF(I14>G14,"부족","!!충분!!")) -> 부족
B15: 암직접치료 입원일당 | D15: =G15-E15 -> #REF! | E15: ='보장분석 비교'!#REF! -> #REF! | G15: ='보장분석 비교'!#REF! -> #REF! | J15: =IF(I15=0,"",IF(I15>G15,"부족","!!충분!!"))
B16: 항암약물방사선 치료비 | D16: =G16-E16 -> 0 | E16: ='보장분석 비교'!$R20 -> 0 | G16: ='보장분석 비교'!$V20 -> 0 | J16: =IF(I16=0,"",IF(I16>G16,"부족","!!충분!!"))
B17: 표적항암약물허가 치료비 | D17: =G17-E17 -> 0 | E17: ='보장분석 비교'!$R21 -> 0 | G17: ='보장분석 비교'!$V21 -> 0 | I17: 5000 | J17: =IF(I17=0,"",IF(I17>G17,"부족","!!충분!!")) -> 부족
A18: 뇌질환 | C18: 뇌혈관질환 진단비 | D18: =G18-E18 -> 0 | E18: ='보장분석 비교'!$R22 -> 0 | G18: ='보장분석 비교'!$V22 -> 0 | I18: 3000 | J18: =IF(I18=0,"",IF(I18>G18,"부족","!!충분!!")) -> 부족
C19: 뇌혈관질환 수술비 | D19: =G19-E19 -> 0 | E19: ='보장분석 비교'!$R23 -> 0 | G19: ='보장분석 비교'!$V23 -> 0 | J19: =IF(I19=0,"",IF(I19>G19,"부족","!!충분!!"))
C20: 뇌졸중 진단비 | D20: =G20-E20 -> 0 | E20: ='보장분석 비교'!$R24 -> 0 | G20: ='보장분석 비교'!$V24 -> 0 | I20: 1000 | J20: =IF(I20=0,"",IF(I20>G20,"부족","!!충분!!")) -> 부족
C21: 뇌출혈 진단비 | D21: =G21-E21 -> 0 | E21: ='보장분석 비교'!$R25 -> 0 | G21: ='보장분석 비교'!$V25 -> 0 | I21: 1000 | J21: =IF(I21=0,"",IF(I21>G21,"부족","!!충분!!")) -> 부족
A22: 심질환 | C22: 허혈성심장질환 진단비 | D22: =G22-E22 -> 0 | E22: ='보장분석 비교'!$R26 -> 0 | G22: ='보장분석 비교'!$V26 -> 0 | I22: 3000 | J22: =IF(I22=0,"",IF(I22>G22,"부족","!!충분!!")) -> 부족
C23: 허혈성심장질환 수술비 | D23: =G23-E23 -> 0 | E23: ='보장분석 비교'!$R27 -> 0 | G23: ='보장분석 비교'!$V27 -> 0 | J23: =IF(I23=0,"",IF(I23>G23,"부족","!!충분!!"))
C24: 심장혈관 진단비 | D24: =G24-E24 -> 0 | E24: ='보장분석 비교'!$R28 -> 0 | G24: ='보장분석 비교'!$V28 -> 0 | I24: 1000 | J24: =IF(I24=0,"",IF(I24>G24,"부족","!!충분!!")) -> 부족
C25: 부정맥 진단비 | D25: =G25-E25 -> 0 | E25: ='보장분석 비교'!$R29 -> 0 | G25: ='보장분석 비교'!$V29 -> 0 | I25: 1000 | J25: =IF(I25=0,"",IF(I25>G25,"부족","!!충분!!")) -> 부족
C26: 급성심근경색 진단비 | D26: =G26-E26 -> 0 | E26: ='보장분석 비교'!$R30 -> 0 | G26: ='보장분석 비교'!$V30 -> 0 | I26: 7000 | J26: =IF(I26=0,"",IF(I26>G26,"부족","!!충분!!")) -> 부족
A27: 수술비 | B27: 상 해 | C27: 상해 수술비 | D27: =G27-E27 -> 0 | E27: ='보장분석 비교'!$R31 -> 0 | G27: ='보장분석 비교'!$V31 -> 0 | I27: 100 | J27: =IF(I27=0,"",IF(I27>G27,"부족","!!충분!!")) -> 부족
C28: 1종 수술비 | D28: =G28-E28 -> 0 | E28: ='보장분석 비교'!$R32 -> 0 | G28: ='보장분석 비교'!$V32 -> 0 | I28: 50 | J28: =IF(I28=0,"",IF(I28>G28,"부족","!!충분!!")) -> 부족
C29: 2종 수술비 | D29: =G29-E29 -> 0 | E29: ='보장분석 비교'!$R33 -> 0 | G29: ='보장분석 비교'!$V33 -> 0 | I29: 100 | J29: =IF(I29=0,"",IF(I29>G29,"부족","!!충분!!")) -> 부족
C30: 3종 수술비 | D30: =G30-E30 -> 0 | E30: ='보장분석 비교'!$R34 -> 0 | G30: ='보장분석 비교'!$V34 -> 0 | I30: 200 | J30: =IF(I30=0,"",IF(I30>G30,"부족","!!충분!!")) -> 부족
C31: 4종 수술비 | D31: =G31-E31 -> 0 | E31: ='보장분석 비교'!$R35 -> 0 | G31: ='보장분석 비교'!$V35 -> 0 | I31: 500 | J31: =IF(I31=0,"",IF(I31>G31,"부족","!!충분!!")) -> 부족
C32: 5종 수술비 | D32: =G32-E32 -> 0 | E32: ='보장분석 비교'!$R36 -> 0 | G32: ='보장분석 비교'!$V36 -> 0 | I32: 1000 | J32: =IF(I32=0,"",IF(I32>G32,"부족","!!충분!!")) -> 부족
B33: 질 병 | C33: 질병 수술비 | D33: =G33-E33 -> 0 | E33: ='보장분석 비교'!$R37 -> 0 | G33: ='보장분석 비교'!$V37 -> 0 | I33: 50 | J33: =IF(I33=0,"",IF(I33>G33,"부족","!!충분!!")) -> 부족
C34: 1종 수술비 | D34: =G34-E34 -> 0 | E34: ='보장분석 비교'!$R38 -> 0 | G34: ='보장분석 비교'!$V38 -> 0 | I34: 10 | J34: =IF(I34=0,"",IF(I34>G34,"부족","!!충분!!")) -> 부족
C35: 2종 수술비 | D35: =G35-E35 -> 0 | E35: ='보장분석 비교'!$R39 -> 0 | G35: ='보장분석 비교'!$V39 -> 0 | I35: 20 | J35: =IF(I35=0,"",IF(I35>G35,"부족","!!충분!!")) -> 부족
C36: 3종 수술비 | D36: =G36-E36 -> 0 | E36: ='보장분석 비교'!$R40 -> 0 | G36: ='보장분석 비교'!$V40 -> 0 | I36: 100 | J36: =IF(I36=0,"",IF(I36>G36,"부족","!!충분!!")) -> 부족
C37: 4종 수술비 | D37: =G37-E37 -> 0 | E37: ='보장분석 비교'!$R41 -> 0 | G37: ='보장분석 비교'!$V41 -> 0 | I37: 500 | J37: =IF(I37=0,"",IF(I37>G37,"부족","!!충분!!")) -> 부족
C38: 5종 수술비 | D38: =G38-E38 -> 0 | E38: ='보장분석 비교'!$R42 -> 0 | G38: ='보장분석 비교'!$V42 -> 0 | I38: 1000 | J38: =IF(I38=0,"",IF(I38>G38,"부족","!!충분!!")) -> 부족
A39: 입원 | B39: 상해 입원일당 | D39: =G39-E39 -> 0 | E39: ='보장분석 비교'!$R43 -> 0 | G39: ='보장분석 비교'!$V43 -> 0 | I39: 7 | J39: =IF(I39=0,"",IF(I39>G39,"부족","!!충분!!")) -> 부족
B40: 질병 입원일당 | D40: =G40-E40 -> 0 | E40: ='보장분석 비교'!$R44 -> 0 | G40: ='보장분석 비교'!$V44 -> 0 | I40: 7 | J40: =IF(I40=0,"",IF(I40>G40,"부족","!!충분!!")) -> 부족
A41: 추가 보장 | B41: 골절 진단비 | D41: =G41-E41 -> 0 | E41: ='보장분석 비교'!$R45 -> 0 | G41: ='보장분석 비교'!$V45 -> 0 | I41: 50 | J41: =IF(I41=0,"",IF(I41>G41,"부족","!!충분!!")) -> 부족
B42: 화상 진단비 | D42: =G42-E42 -> 0 | E42: ='보장분석 비교'!$R46 -> 0 | G42: ='보장분석 비교'!$V46 -> 0 | I42: 20 | J42: =IF(I42=0,"",IF(I42>G42,"부족","!!충분!!")) -> 부족
...

Sheet 해지할회사정리
B2: 해지해야될 회사별 목록 정리
B4: 원금융서비스 입니다
B5: 해지하실것들 알려드리겠습니다. 해지후 해지확인서 팩스발송 부탁드리겠습니다 ^^
B6: Fax.
B8: 해지할 회사 목록
B10: 회사이름 | C10: 상품명이름 | D10: 납입보험료 | E10: 해지이유 | F10: 고객센터 | G10: 비고
B28: 배서할 회사 목록
B30: 회사이름 | C30: 상품명이름 | D30: 납입보험료 | E30: 배서이유 | F30: 고객센터 | G30: 비고

Sheet 회사고객센터
A1: 손해보험사 고객센터 | D1: 생명보험사 고객센터
A2: 한화손해 | B2: 1566-8000 | D2: 동양생명 | E2: 1577-1004
A3: AIG손해 | B3: 1544-2792 | D3: 흥국생명 | E3: 1588-2288
A4: 롯데손해 | B4: 1588-3344 | D4: 신한라이프 | E4: 1588-5580
A5: DB손해 | B5: 1588-0100 | D5: KB생명 | E5: 1588-3374
A6: 현대해상 | B6: 1588-5656 | D6: KDB생명 | E6: 1588-4040
A7: 농협화재 | B7: 1644-9000 | D7: ABL생명 | E7: 1588-6500
A8: 삼성화재 | B8: 1588-5114 | D8: 푸르덴셜생명 | E8: 1588-3374
A9: MG손해 | B9: 1588-5959 | D9: DGB생명 | E9: 1588-4770
A10: KB손해 | B10: 1544-0114 | D10: 한화생명 | E10: 1588-6363
A11: 흥국화재 | B11: 1688-1688 | D11: 삼성생명 | E11: 1588-3114
A12: 메리츠 | B12: 1566-7711 | D12: 교보생명 | E12: 1588-1001
D13: 미래에셋생명 | E13: 1588-0220
D14: 농협생명 | E14: 1544-4000
D15: 라이나생명 | E15: 1588-0058
D16: 메트라이프생명 | E16: 1588-9600
D17: DB생명 | E17: 1588-3131

Sheet 심뇌혈관보장범위

Sheet 암분류표

Sheet 후유장해지급률
